Workbook

Sheet 1. Overview & Checklist
A1: ZORA CLIENT ONBOARDING TEMPLATE — OVERVIEW & CHECKLIST
A2: Use this checklist to track progress across all onboarding sheets. Complete sheets in order — later sheets depend on earlier ones. Sheet 1 (this sheet) is completed last as a summary of everything gathered.
A3: ℹ HOW TO USE THIS TEMPLATE: 1) Start with Sheet 2 (Table Info) — fill in the client's database tables. 2) Proceed through sheets in order. 3) Yellow rows = pre-filled examples from the reference model — replace with client data. 4) Update the Status column below as each sheet is completed. 5) The AI team uses all sheets to configure and test the product before go-live.
A4: PROJECT INFORMATION
B5: Client Name | C5: Covestro
B6: Project / Engagement Name | C6: Zora AI Pilot
B7: Product Module(s) in Scope | C7: [e.g. Ask Zora, KPI Cards, Performance Pulse, Daily News]
B8: Primary Client Contact | C8: [Name, Title, Email]
B9: Zora Team Lead | C9: [Name]
B10: Target Go-Live Date | C10: [DD/MM/YYYY]
B11: Data Source System(s) | C11: [e.g. SAP S/4HANA, Oracle EBS, Salesforce CRM, Excel Budget Model]
B12: Reporting Currency | C12: [e.g. USD — all monetary amounts in reporting currency]
B13: Fiscal Year Start Month | C13: [e.g. January — or April if non-calendar fiscal year]
A15: SHEET-BY-SHEET COMPLETION CHECKLIST
A16: # | B16: Sheet Name | C16: What This Sheet Captures | D16: Data Provider (Client / Team) | E16: Format Required | F16: Priority | G16: Status
A17: 2 | B17: Table Info | C17: All database tables the AI can query: table names, grain (what one row represents), when to use each table, when NOT to use it, and which metrics each table supports. | D17: Client (data/IT team) + Zora Team validation | E17: Fill the Table Info sheet directly. One row per table. | F17: 🔴 Critical (required first) | G17: NOT STARTED
A18: 3 | B18: Column Info | C18: Every column in every table: business-friendly name, plain-English description, data type, sample values, and friendly_names (the phrases users say that map to this column). | D18: Client (data/IT team) + Zora Team validation | E18: Fill the Column Info sheet. One row per column. friendly_names column is especially important — more = better. | F18: 🔴 Critical (required first) | G18: NOT STARTED
A19: 4 | B19: Metrics | C19: Every metric the AI can compute: formula, keywords that trigger it, SQL template with {placeholders}, critical usage notes, and example arguments. | D19: Zora Team (with client sign-off on formulas) | E19: Fill the Metrics sheet. One row per metric. Client must confirm formula definitions (e.g. how they define DSO, what budget version to use). | F19: 🔴 Critical | G19: NOT STARTED
A20: 5 | B20: GT — Ask Zora | C20: Ground truth question-answer pairs: sample user questions, source tables, step-by-step calculation logic, verified SQL, and expected numerical answers. | D20: Functional team (client SMEs) + Zora Team builds SQL | E20: Fill the GT sheet. Minimum 10 rows covering all key question types. Client SMEs must verify expected_answer values against their source of truth. | F20: 🔴 Critical | G20: NOT STARTED
A21: 6 | B21: KPI Cards | C21: KPI card widget definitions: the headline SQL (returns one number), the comparison badge SQL (e.g. MoM change), footnote, target value, and favorable direction. | D21: Functional team (client) + Zora Team builds SQL | E21: Fill the KPI Cards sheet. One row per card. Each SQL must return exactly ONE row. Test against live data before marking complete. | F21: 🟡 High | G21: NOT STARTED
A22: 7 | B22: Performance Pulse | C22: Performance Pulse widget definitions: the SQL that retrieves data, ground truth numbers, the exact output format template (chart + table + narrative structure), and a sample prompt that triggers each widget. | D22: Functional team (client) + Zora Team | E22: Fill the Performance Pulse sheet. One row per widget. ground_truth must be verified. output_format is the exact AI response template. | F22: 🟡 High | G22: NOT STARTED
A23: 8 | B23: Daily News Logic | C23: Daily auto-generated news items: what each item shows, headline and body templates, calculation logic, verified SQL, ground truth numbers, and chart specification. | D23: Functional team (client) + Zora Team | E23: Fill the Daily News sheet. One row per news item. Test SQL against live data. Mark status PASS only when AI output matches ground truth. | F23: 🟡 High | G23: NOT STARTED
A24: 9 | B24: Fiscal & Rounding Rules | C24: Client-specific configuration: fiscal year start month, fiscal quarter mapping, reporting currency, number formatting rules, rounding conventions, budget version to use, and KPI targets. | D24: Client (Finance / FP&A team) | E24: Fill the Fiscal & Rounding Rules sheet directly. All fields required — incorrect fiscal config causes wrong period filters in every query. | F24: 🔴 Critical | G24: NOT STARTED
A25: 10 | B25: Requirements & Notes | C25: Master prompt context (who the AI is and how it should behave), known data issues and limitations, open questions for the client, and sign/rounding conventions. | D25: Zora Team + Client review | E25: Fill the Requirements & Notes sheet. Master Prompt Context section is particularly important — it defines AI behaviour. | F25: 🟡 High | G25: NOT STARTED
A27: STATUS KEY: NOT STARTED = work not begun | IN PROGRESS = actively being filled | CLIENT REVIEW = submitted to client for verification | COMPLETE = verified and signed off
A29: ⚠ DEPENDENCY ORDER: Sheets 2 (Table Info) and 3 (Column Info) must be completed FIRST — all SQL in later sheets references the exact table and column names defined there. Sheet 4 (Metrics) must be complete before Sheet 5 (GT). Sheet 9 (Fiscal & Rounding Rules) must be complete before any AI testing begins.

Sheet 2. Table Info
A1: TABLE INFO
A2: One row per table in the client database. Describes purpose, grain, usage rules and key joins. Fill every column — the AI uses this to decide WHICH table to query.
A3: ℹ Instructions: Add one row per table. table_name must exactly match the database table name. grain = what one row represents (e.g. 'one row per billing line'). when_to_use / when_not_to_use are critical — they prevent the AI from joining wrong tables. Yellow rows are filled examples; replace with your own data.
A4: Covestro | J4: Covestro - meta data
A5: table_name | B5: alias | C5: table_type | D5: primary_key | E5: grain | F5: when_to_use | G5: when_not_to_use | H5: string_columns | I5: possible_metrics | J5: notes
A6: AR_KeyDate | B6: kd | F6: Use for accounts receivable snapshot analysis at a specific reporting date. Use for overdue receivables, not-yet-due receivables, receivables balances, WAT Target, WOC Target, receivables aging, credit exposure, customer payment terms, and working capital reporting. Slice by customer, geography, product, sales organization, industry, marketing hierarchy, or reporting unit. | G6: Do not use for sales revenue, sales volume, margin, product cost, shipment, or OTIF analyses. Do not use for operational collection performance trends over time; use AR-PM instead | H6: ['BG, booked', 'BG, booked2', 'Company Code', 'Company Code2', 'Core Business Indicator', 'Core Business Indicator2', 'Country ship-to', 'Country ship-to2', 'Country sold-to', 'Country sold-to2', 'Cust Hier1', 'Cust Hier12', 'Cust Hier2', 'Cust Hier22', 'Cust Hier3', 'Cust Hier32', 'Customer Channel', 'Customer Channel2', 'Customer Cluster', 'Customer Cluster2', 'Extern. Sales Office', 'Extern. Sales Office2', 'FI-ML0', 'FI-ML02', 'Fiscal year/period', 'Fiscal year/period2', 'Int. Sales Group', 'Int. Sales Group2', 'Key Industry', 'Key Industry2', 'Marketing Customer ship-to', 'Marketing Customer ship-to2', 'Marketing Customer sold-to', 'Marketing Customer sold-to2', 'Marketing Level 0', 'Marketing Level 02', 'Marketing Level 1', 'Marketing Level 12', 'Marketing Level 2', 'Marketing Level 22', 'Marketing Level 3', 'Marketing Level 32', 'Marketing Level 4', 'Marketing Level 42', 'Material', 'Material2', 'Net due date', 'PH3 Cluster', 'PH3 Cluster2', 'Plant', 'Plant2', 'Posting date', 'Prod.Hier.1', 'Prod.Hier.12', 'Prod.Hier.2', 'Prod.Hier.22', 'Prod.Hier.3', 'Prod.Hier.32', 'Prod.Hier.4', 'Prod.Hier.42', 'Prod.Hier.5', 'Prod.Hier.52', 'Prod.Hier.6', 'Prod.Hier.62', 'Produced Material', 'Produced Material2', 'Region ship-to', 'Region ship-to2', 'Region sold-to', 'Region sold-to2', 'Reporting Unit, book', 'Reporting Unit, book2', 'Risk Class', 'Risk Class2', 'SBE', 'SBE2', 'Sales Organization', 'Sales Organization2', 'Ship-to', 'Ship-to2', 'ShipTo State/ Province', 'ShipTo State/ Province2', 'Sold-to', 'Sold-to2', 'SoldTo State/ Province', 'SoldTo State/ Province2', 'Subregion ship-to', 'Subregion ship-to2', 'Subregion sold-to', 'Subregion sold-to2', 'Unpacked good', 'Unpacked good2', 'KPI AR-KeyDate: Amount in EUR', 'KPI AR-KeyDate: Counter', 'KPI AR-KeyDate: Net Value of Billing Item (DC)', 'KPI AR-KeyDate: Weighted WoC Target days', 'KPI AR-KeyDate: Weighted target days'] | I6: WAT Target; WOC Target; Overdue; Not yet due; % Overdue of Receivables; Receivables; Line items; Net value of billing item; Weighted WoC target days; Weighted target days
A7: AR_PM | B7: pm | F7: Use for receivables performance monitoring over time. Use for EDO (Effective Days Outstanding), WAT Receivables, WDD (Weighted Delay Days), collection effectiveness, payment behavior, performance days, posting days, and deviations against WoC targets. Ideal for working capital performance management and collection trend analysis. | G7: Do not use for current AR balance snapshots, overdue balances, or receivable aging at a key date; use AR-KeyDate instead. Do not use for sales, margin, pricing, shipment, or OTIF analyses. | H7: ['BG, booked', 'BG, booked2', 'Company Code', 'Company Code2', 'Core Business Indicator', 'Core Business Indicator2', 'Country ship-to', 'Country ship-to2', 'Country sold-to', 'Country sold-to2', 'Cust Hier1', 'Cust Hier12', 'Cust Hier2', 'Cust Hier22', 'Cust Hier3', 'Cust Hier32', 'Customer Channel', 'Customer Channel2', 'Customer Cluster', 'Customer Cluster2', 'Extern. Sales Office', 'Extern. Sales Office2', 'FI-ML0', 'FI-ML02', 'Fiscal year/period', 'Fiscal year/period2', 'Int. Sales Group', 'Int. Sales Group2', 'Int. Sales office', 'Int. Sales office2', 'Key Industry', 'Key Industry2', 'Marketing Customer ship-to', 'Marketing Customer ship-to2', 'Marketing Customer sold-to', 'Marketing Customer sold-to2', 'Marketing Level 0', 'Marketing Level 02', 'Marketing Level 1', 'Marketing Level 12', 'Marketing Level 2', 'Marketing Level 22', 'Marketing Level 3', 'Marketing Level 32', 'Marketing Level 4', 'Marketing Level 42', 'Material', 'Material2', 'Net due date', 'PH3 Cluster', 'PH3 Cluster2', 'Plant', 'Plant2', 'Posting date', 'Prod.Hier.1', 'Prod.Hier.12', 'Prod.Hier.2', 'Prod.Hier.22', 'Prod.Hier.3', 'Prod.Hier.32', 'Prod.Hier.4', 'Prod.Hier.42', 'Prod.Hier.5', 'Prod.Hier.52', 'Prod.Hier.6', 'Prod.Hier.62', 'Produced Material', 'Produced Material2', 'Region ship-to', 'Region ship-to2', 'Region sold-to', 'Region sold-to2', 'Reporting Unit, book', 'Reporting Unit, book2', 'Risk Class', 'Risk Class2', 'SBE', 'SBE2', 'Sales Organization', 'Sales Organization2', 'Ship-to', 'Ship-to2', 'ShipTo State/ Province', 'ShipTo State/ Province2', 'Sold-to', 'Sold-to2', 'SoldTo State/ Province', 'SoldTo State/ Province2', 'Subregion ship-to', 'Subregion ship-to2', 'Subregion sold-to', 'Subregion sold-to2', 'Unpacked good', 'Unpacked good2', 'KPI AR-PM: Amount EUR', 'KPI AR-PM: Counter', 'KPI AR-PM: Diff WoC Target', 'KPI AR-PM: EDO (Effective Days Outstanding)', 'KPI AR-PM: Performance Days', 'KPI AR-PM: Posting Days', 'KPI AR-PM: WAT Receivables', 'KPI AR-PM: WDD (Weighted Delay Days)'] | I7: Receivables - PM; Line items - PM; WoC deviation from target; Effective days outstanding; Performance days; Posting days; WAT Receivables; Weighted delay days
A8: COPA | B8: cop | F8: Use for sales and commercial performance analysis. Use for Gross Sales, Net Sales, Net Proceeds, Sales Deductions, Sales Adjustments, Selling Price, price realization, revenue growth, customer/product sales performance, and commercial reporting. Use when the focus is sales value rather than profitability. | G8: Do not use for detailed profitability metrics such as MI1, MI2a, product cost analysis, manufacturing cost analysis, AR reporting, or delivery reliability metrics. Use COSMOS for margin and profitability calculations. | H8: ['BG, booked', 'BG, booked2', 'Company Code', 'Company Code2', 'Core Business Indicator', 'Core Business Indicator2', 'Country ship-to', 'Country ship-to2', 'Country sold-to', 'Country sold-to2', 'Cust Hier1', 'Cust Hier12', 'Cust Hier2', 'Cust Hier22', 'Cust Hier3', 'Cust Hier32', 'Customer Channel', 'Customer Channel2', 'Customer Cluster', 'Customer Cluster2', 'Extern. Sales Office', 'Extern. Sales Office2', 'Fiscal year/period', 'Fiscal year/period2', 'Int. Sales Group', 'Int. Sales Group2', 'Int. Sales office', 'Int. Sales office2', 'Key Industry', 'Key Industry2', 'Marketing Customer ship-to', 'Marketing Customer ship-to2', 'Marketing Customer sold-to', 'Marketing Customer sold-to2', 'Marketing Level 0', 'Marketing Level 02', 'Marketing Level 1', 'Marketing Level 12', 'Marketing Level 2', 'Marketing Level 22', 'Marketing Level 3', 'Marketing Level 32', 'Marketing Level 4', 'Marketing Level 42', 'Material', 'Material2', 'PH3 Cluster', 'PH3 Cluster2', 'Plant', 'Plant2', 'Posting date', 'Prod.Hier.1', 'Prod.Hier.12', 'Prod.Hier.2', 'Prod.Hier.22', 'Prod.Hier.3', 'Prod.Hier.32', 'Prod.Hier.4', 'Prod.Hier.42', 'Prod.Hier.5', 'Prod.Hier.52', 'Prod.Hier.6', 'Prod.Hier.62', 'Produced Material', 'Produced Material2', 'Region ship-to', 'Region ship-to2', 'Region sold-to', 'Region sold-to2', 'Reporting Unit, book', 'Reporting Unit, book2', 'SBE', 'SBE2', 'Sales Organization', 'Sales Organization2', 'Ship-to', 'Ship-to2', 'ShipTo State/ Province', 'ShipTo State/ Province2', 'Sold-to', 'Sold-to2', 'SoldTo State/ Province', 'SoldTo State/ Province2', 'Subregion ship-to', 'Subregion ship-to2', 'Subregion sold-to', 'Subregion sold-to2', 'Unpacked good', 'Unpacked good2', 'KPI COPA: Gross Sales Qty', 'KPI COPA: Gross sales', 'KPI COPA: Net proceeds', 'KPI COPA: Net sales', 'KPI COPA: Sales adjustments', 'KPI COPA: Sales deductions'] | I8: Net Sales Growth (%); Selling Price; Gross sales quantity (CO-PA); Gross sales (CO-PA); Net proceeds (CO-PA); Net sales (CO-PA); Sales adjustments (CO-PA); Sales deductions (CO-PA)
A9: COSMOS | B9: cos | F9: Use for profitability, margin, and cost analysis. Use for MI1, MI2a, MI1 %, MI2a %, MI1 per kg, MI2a per kg, Variable Product Costs, Variable Product Costs per kg, Manufacturing Costs, Net Sales, Gross Sales Qty, Net Proceeds, Exchange Rate Effects, and overall business profitability reporting. This is the primary table for margin management and product profitability analysis. | G9: Do not use for accounts receivable analysis, delivery performance monitoring, shipment execution analysis, or operational logistics KPIs. Do not use when only COPA sales values are required and profitability metrics are not needed. | H9: ['BG, booked', 'BG, booked2', 'Calendar Day', 'Company Code', 'Company Code2', 'Core Business Indicator', 'Core Business Indicator2', 'Country ship-to', 'Country ship-to2', 'Country sold-to', 'Country sold-to2', 'Cust Hier1', 'Cust Hier12', 'Cust Hier2', 'Cust Hier22', 'Cust Hier3', 'Cust Hier32', 'Customer Channel', 'Customer Channel2', 'Customer Cluster', 'Customer Cluster2', 'Exchange rate effect', 'Extern. Sales Office', 'Extern. Sales Office2', 'Fiscal year/period', 'Fiscal year/period2', 'Int. Sales Group', 'Int. Sales Group2', 'Int. Sales office', 'Int. Sales office2', 'Key Industry', 'Key Industry2', 'Marketing Customer ship-to', 'Marketing Customer ship-to2', 'Marketing Customer sold-to', 'Marketing Customer sold-to2', 'Marketing Level 0', 'Marketing Level 02', 'Marketing Level 1', 'Marketing Level 12', 'Marketing Level 2', 'Marketing Level 22', 'Marketing Level 3', 'Marketing Level 32', 'Marketing Level 4', 'Marketing Level 42', 'Material', 'Material2', 'PH3 Cluster', 'PH3 Cluster2', 'Plant', 'Plant2', 'Prod.Hier.1', 'Prod.Hier.12', 'Prod.Hier.2', 'Prod.Hier.22', 'Prod.Hier.3', 'Prod.Hier.32', 'Prod.Hier.4', 'Prod.Hier.42', 'Prod.Hier.5', 'Prod.Hier.52', 'Prod.Hier.6', 'Prod.Hier.62', 'Produced Material', 'Produced Material2', 'Region ship-to', 'Region ship-to2', 'Region sold-to', 'Region sold-to2', 'Reporting Unit, book', 'Reporting Unit, book2', 'SBE', 'SBE2', 'Sales Organization', 'Sales Organization2', 'Ship-to', 'Ship-to2', 'ShipTo State/ Province', 'ShipTo State/ Province2', 'Sold-to', 'Sold-to2', 'SoldTo State/ Province', 'SoldTo State/ Province2', 'Subregion ship-to', 'Subregion ship-to2', 'Subregion sold-to', 'Subregion sold-to2', 'Unpacked good', 'Unpacked good2', 'KPI COSMOS: Consolidated Marginal Income II a', 'KPI COSMOS: Consolidated Marginal Income I', 'KPI COSMOS: Gross Sales', 'KPI COSMOS: Gross Sales Qty (in+ex)', 'KPI COSMOS: Net Proceeds', 'KPI COSMOS: Net Sales', 'KPI COSMOS: Product Costs, Var.', 'KPI COSMOS: Sales Adjustments', 'KPI COSMOS: Sales Deductions', 'KPI COSMOS: Total Manufacturing Costs, Fix'] | I9: Var. Product Costs per kg; MI1 in %; Margin I per kg; MI2a in %; MI2a per kg; Consolidated marginal income I; Consolidated marginal income II a; Gross sales (COSMOS); Gross sales quantity internal + external (COSMOS); Net proceeds (COSMOS); Net sales (COSMOS); Variable product costs; Sales Adjustments (COSMOS); Sales deductions (COSMOS); Total fixed manufacturing costs
A10: OTIF | B10: o | F10: Use for supply chain and customer service performance reporting. Use for OTIF Rate, delivery reliability, on-time delivery, in-full delivery, late deliveries, transportation performance, quantity deviations, overdeliveries, underdeliveries, carrier performance, and logistics service level analysis. | G10: Do not use for sales revenue, profitability, pricing, receivables, working capital, or financial performance reporting. Delivery quantities should be used for service-level analysis only, not official sales volume reporting. | H10: ['Act. GI Day', 'BG, booked', 'BG, booked2', 'Carrier', 'Carrier2', 'Company Code', 'Company Code2', 'Core Business Indicator', 'Core Business Indicator2', 'Country ship-to', 'Country ship-to2', 'Country sold-to', 'Country sold-to2', 'Delivery plant', 'Delivery plant2', 'Extern. Sales Office', 'Extern. Sales Office2', 'Int. Sales Group', 'Int. Sales Group2', 'Int. Sales office', 'Int. Sales office2', 'Key Industry', 'Key Industry2', 'Leg transp. Chain', 'Leg transp. Chain2', 'Loading Country', 'Loading Country2', 'Loading location', 'Loading location2', 'Marketing Customer ship-to', 'Marketing Customer ship-to2', 'Marketing Customer sold-to', 'Marketing Customer sold-to2', 'Marketing Level 0', 'Marketing Level 02', 'Marketing Level 1', 'Marketing Level 12', 'Marketing Level 2', 'Marketing Level 22', 'Marketing Level 3', 'Marketing Level 32', 'Marketing Level 4', 'Marketing Level 42', 'Material', 'Material2', 'Mode of transport', 'Mode of transport2', 'PH3 Cluster', 'PH3 Cluster2', 'Plant', 'Plant2', 'Prod.Hier.1', 'Prod.Hier.12', 'Prod.Hier.2', 'Prod.Hier.22', 'Prod.Hier.3', 'Prod.Hier.32', 'Prod.Hier.4', 'Prod.Hier.42', 'Prod.Hier.5', 'Prod.Hier.52', 'Prod.Hier.6', 'Prod.Hier.62', 'Produced Material', 'Produced Material2', 'Region ship-to', 'Region ship-to2', 'Region sold-to', 'Region sold-to2', 'Reporting Unit, book', 'Reporting Unit, book2', 'SBE', 'SBE2', 'Ship-to', 'Ship-to2', 'ShipTo State/ Province', 'ShipTo State/ Province2', 'Sold-to', 'Sold-to2', 'SoldTo State/ Province', 'SoldTo State/ Province2', 'Subregion ship-to', 'Subregion ship-to2', 'Subregion sold-to', 'Subregion sold-to2', 'T3 Arr. Date planned', 'T3 Arr. date actual', 'T3 Loading Loc. ROI', 'T3 Loading Loc. ROI2', 'T3 SH Shipper', 'T3 SH Shipper2', 'TM Destin. Location', 'TM Destin. Location2', 'Unpacked good', 'Unpacked good2', 'KPI OTIF: # OTIF', 'KPI OTIF: # late GI', 'KPI OTIF: # late IF', 'KPI OTIF: # late NIF', 'KPI OTIF: # late create', 'KPI OTIF: # late transport', 'KPI OTIF: # not in full', 'KPI OTIF: # on time', 'KPI OTIF: # total deliveries', 'KPI OTIF: # total late', 'KPI OTIF: # total late+OT NIF', 'KPI OTIF: 1. Agreed quantity KG', 'KPI OTIF: Delivery Quantity KG', 'KPI OTIF: Overdelivery KG', 'KPI OTIF: Qty deviation KG', 'KPI OTIF: Underdelivery KG', 'KPI OTIF: # OT not in full' ] | I10: OTIF Rate; On-time but incomplete deliveries; OTIF-compliant deliveries; Deliveries with late goods issue; Late and complete deliveries; Late and not-in-full deliveries (NIF); Deliveries with late order creation; Deliveries with transport delay; Incomplete deliveries; On-time deliveries; Total deliveries; Total late deliveries; Total late and/or incomplete deliveries; Agreed delivery quantity; Actually delivered quantity; Overdelivery quantity; Quantity deviation; Underdelivery quantity
A11: Sales | B11: s | F11: Use for order fulfillment, shipment, and delivery volume analysis. Use for Delivery Quantity KG, shipment values, delivery execution, planned vs. actual delivery dates, goods issue tracking, delivery trends, and Volume Growth (%). This table is best for operational sales volume and logistics execution reporting. | G11: Do not use for profitability calculations, marginal income reporting, receivables analysis, pricing calculations, or OTIF service-level calculations. For revenue use COPA; for margin use COSMOS; for delivery reliability use OTIF. | H11: ['Act. GI Day', 'Actual delivery date', 'BG, booked', 'BG, booked2', 'Company Code', 'Company Code2', 'Core Business Indicator', 'Core Business Indicator2', 'Country ship-to', 'Country ship-to2', 'Country sold-to', 'Country sold-to2', 'Created on', 'Cust Hier1', 'Cust Hier12', 'Cust Hier2', 'Cust Hier22', 'Cust Hier3', 'Cust Hier32', 'Customer Cluster', 'Customer Cluster2', 'Delivery date plann.', 'Document currency', 'Document currency2', 'Extern. Sales Office', 'Extern. Sales Office2', 'Int. Sales Group', 'Int. Sales Group2', 'Int. Sales office', 'Int. Sales office2', 'Key Industry', 'Key Industry2', 'Marketing Customer ship-to', 'Marketing Customer ship-to2', 'Marketing Customer sold-to', 'Marketing Customer sold-to2', 'Marketing Level 0', 'Marketing Level 02', 'Marketing Level 1', 'Marketing Level 12', 'Marketing Level 2', 'Marketing Level 22', 'Marketing Level 3', 'Marketing Level 32', 'Marketing Level 4', 'Marketing Level 42', 'Material', 'Material2', 'PH3 Cluster', 'PH3 Cluster2', 'Plan. goods is. date', 'Plant', 'Plant2', 'Prod.Hier.1', 'Prod.Hier.12', 'Prod.Hier.2', 'Prod.Hier.22', 'Prod.Hier.3', 'Prod.Hier.32', 'Prod.Hier.4', 'Prod.Hier.42', 'Prod.Hier.5', 'Prod.Hier.52', 'Prod.Hier.6', 'Prod.Hier.62', 'Prod.Hier.622', 'Prod.Hier.6222', 'Produced Material', 'Produced Material2', 'Region ship-to', 'Region ship-to2', 'Region sold-to', 'Region sold-to2', 'Reporting Unit, book', 'Reporting Unit, book2', 'SBE', 'SBE2', 'Ship-to', 'Ship-to2', 'ShipTo State/ Province', 'ShipTo State/ Province2', 'Sold-to', 'Sold-to2', 'SoldTo State/ Province', 'SoldTo State/ Province2', 'Subregion ship-to', 'Subregion ship-to2', 'Subregion sold-to', 'Subregion sold-to2', 'Unpacked good', 'Unpacked good2', 'KPI Sales: Delivery Quantity KG', 'KPI Sales: Net value deliv. DC', 'KPI Sales: Net value delivery EUR'] | I11: Volume Growth (%); Order Volume; Net value of delivery item; Net value of delivery
A12: Covestro | B12: Deloitte FDE
A13: Fields to be clarified - High priority | B13: Fields to be clarified - High priority
A14: Fields to be clarified - Mid priority | B14: Fields to be clarified - Mid priority
A15: Fields to be clarified - Low priority | B15: Fields to be clarified - Low priority
A17: 🟡 Yellow rows = example data from product reference model. Replace with your client's actual table names, descriptions and business rules before use.

Sheet 3. Column Info
A1: COLUMN INFO
A2: One row per column in each table. Defines business meaning, data type, and the natural-language aliases the AI uses to map user questions to the right column.
A3: ℹ Instructions: Add one row per column per table. business_name = plain English label shown in responses. friendly_names = comma-separated phrases users might say (e.g. 'revenue, sales, net revenue'). The AI uses friendly_names to resolve ambiguous questions — the more you add, the more accurate it is. is_key = TRUE for primary/foreign keys. is_required = TRUE if the column is always populated.
A5: table_name | B5: column_name | C5: technical_name | D5: business_name | E5: description | F5: data_type | G5: is_key | H5: is_required | I5: sample_values | J5: notes | K5: friendly_names
A6: AR_KeyDate | B6: BG, booked | C6: BG__BOOKED | D6: Booked business group | E6: Indicator for the booked business group (BG) of a document. Used in profitability analysis (CO-PA) and reporting to delimit booking units within a company code. | F6: NUMBER(2) | H6: False | I6: 70 | J6: NOT NULL, integer only, max abs value 97 | K6: business group; booked business group; BG; business unit group; reporting business group
A7: AR_KeyDate | B7: BG, booked2 | C7: BG__BOOKED2 | D7: Booked business group (TEXT) | F7: VARCHAR2(40) | H7: False | I7: PM | J7: NOT NULL, text/mixed, max length 20
A8: AR_KeyDate | B8: Company Code | C8: COMPANY_CODE | D8: Company code | E8: A company code is the smallest organizational unit for which a complete, self-contained set of accounts can be drawn up. It typically corresponds to a legally independent company within the group. All documents are assigned to a company code. Each legal entity has its own company code. | F8: NUMBER(4) | H8: False | I8: 889 | J8: NOT NULL, integer only, max abs value 2422 | K8: company; legal entity; entity; subsidiary; business entity; reporting company
A9: AR_KeyDate | B9: Company Code2 | C9: COMPANY_CODE2 | D9: Company code (TEXT) | F9: VARCHAR2(40) | H9: False | I9: Covestro Private/Ind | J9: NOT NULL, text/mixed, max length 20
A10: AR_KeyDate | B10: Core Business Indicator | C10: CORE_BUSINESS_INDICATOR | D10: Core business indicator | E10: A flag that indicates whether a business transaction belongs to company' s core business or is assigned to a sideline business. Relevant for separating core and non-core activities in reporting. Values C, P, and T together represent Core Business classification. | F10: VARCHAR2(2) | H10: False | I10: C | J10: NOT NULL, text/mixed, max length 1 | K10: core business; non-core business; business classification; core activity; strategic business flag
A11: AR_KeyDate | B11: Core Business Indicator2 | C11: CORE_BUSINESS_INDICATOR2 | D11: Core business indicator (TEXT) | F11: VARCHAR2(40) | H11: False | I11: Core external market | J11: NOT NULL, text/mixed, max length 20
A12: AR_KeyDate | B12: Country ship-to | C12: COUNTRY_SHIP_TO | D12: Country of the ship-to party | E12: The country of the ship-to partner (goods recipient) from the customer master. Used for geographic analyses, foreign trade statistics and export controls. Part of the customer attributes in SAP S/4HANA (Ship-to Country). | F12: VARCHAR2(4) | H12: False | I12: IN | J12: NOT NULL, text/mixed, max length 2 | K12: ship-to country; delivery country; destination country; receiving country; customer destination country
A13: AR_KeyDate | B13: Country ship-to2 | C13: COUNTRY_SHIP_TO2 | D13: Country of the ship-to party (TEXT) | F13: VARCHAR2(28) | H13: False | I13: India | J13: NOT NULL, text/mixed, max length 14
A14: AR_KeyDate | B14: Country sold-to | C14: COUNTRY_SOLD_TO | D14: Country of the sold-to party | E14: The country of the sold-to partner (ordering customer) from the customer master. Used for geographic sales analyses. Part of the customer attributes in SAP S/4HANA (Sold-to Country). | F14: VARCHAR2(4) | H14: False | I14: IN | J14: NOT NULL, text/mixed, max length 2 | K14: customer country; sold-to country; sales country; ordering country; market country
A15: AR_KeyDate | B15: Country sold-to2 | C15: COUNTRY_SOLD_TO2 | D15: Country of the sold-to party (TEXT) | F15: VARCHAR2(30) | H15: False | I15: India | J15: NOT NULL, text/mixed, max length 15
A16: AR_KeyDate | B16: Cust Hier1 | C16: CUST_HIER1 | D16: Customer hierarchy level 1 | E16: The highest level of the customer hierarchy. Customer hierarchies are flexible, multi-level structures that reflect the organizational structure of customers. Level 1 typically represents the parent company (e.g. group headquarters). Used for pricing and reporting. | F16: VARCHAR2(4) | H16: False | I16: 33 | J16: NOT NULL, text/mixed, max length 2 | K16: customer hierarchy level 1; parent customer; global parent; customer group level 1; top customer hierarchy
A17: AR_KeyDate | B17: Cust Hier12 | C17: CUST_HIER12 | D17: Customer hierarchy level 1 (TEXT) | F17: VARCHAR2(38) | H17: False | I17: TUR PU Specialties | J17: NOT NULL, text/mixed, max length 19
A18: AR_KeyDate | B18: Cust Hier2 | C18: CUST_HIER2 | D18: Customer hierarchy level 2 | E18: Second level of the customer hierarchy. Typically represents an intermediate level (e.g. regional subsidiary) within the customer hierarchy. | F18: VARCHAR2(6) | H18: False | I18: 604 | J18: NOT NULL, text/mixed, max length 3 | K18: customer hierarchy level 2; customer group level 2; regional customer group; hierarchy level 2
A19: AR_KeyDate | B19: Cust Hier22 | C19: CUST_HIER22 | D19: Customer hierarchy level 2 (TEXT) | F19: VARCHAR2(40) | H19: False | I19: TUR Auto | J19: NOT NULL, text/mixed, max length 20
A20: AR_KeyDate | B20: Cust Hier3 | C20: CUST_HIER3 | D20: Customer hierarchy level 3 | E20: Third level of the customer hierarchy. Represents the lowest standard hierarchy level (e.g. individual branch or subsidiary of the customer). | F20: VARCHAR2(10) | H20: False | I20: 71008 | J20: NOT NULL, text/mixed, max length 5 | K20: customer hierarchy level 3; customer group level 3; local customer group; hierarchy level 3
A21: AR_KeyDate | B21: Cust Hier32 | C21: CUST_HIER32 | D21: Customer hierarchy level 3 (TEXT) | F21: VARCHAR2(40) | H21: False | I21: TU Auto LoadFloorSpr | J21: NOT NULL, text/mixed, max length 20
A22: AR_KeyDate | B22: Customer Channel | C22: CUSTOMER_CHANNEL | D22: Customer sales channel | E22: An attribute that classifies a customer's sales channel(e.g. direct sales, distributor, e-commerce). Used for segmentation and sales analyses in BW reporting. | F22: VARCHAR2(6) | H22: False | I22: D01 | J22: NOT NULL, text/mixed, max length 3 | K22: sales channel; customer channel; distribution channel; route to market; go-to-market channel
A23: AR_KeyDate | B23: Customer Channel2 | C23: CUSTOMER_CHANNEL2 | D23: Customer sales channel (TEXT) | F23: VARCHAR2(56) | H23: False | I23: DIR-Direct | J23: NOT NULL, text/mixed, max length 28
A24: AR_KeyDate | B24: Customer Cluster | C24: CUSTOMER_CLUSTER | D24: Customer cluster | E24: An attribute for grouping customers by strategic or analytical criteria (e.g. size, potential, industry). Used in sales controlling and segmentation analysis. | F24: VARCHAR2(8) | H24: False | I24: 1312 | J24: NOT NULL, text/mixed, max length 4 | K24: customer segment; customer cluster; customer category; strategic segment; customer grouping
A25: AR_KeyDate | B25: Customer Cluster2 | C25: CUSTOMER_CLUSTER2 | D25: Customer cluster (TEXT) | F25: VARCHAR2(74) | H25: False | I25: PMC-TUR-SPEC-Others | J25: NOT NULL, text/mixed, max length 37
A26: AR_KeyDate | B26: Extern. Sales Office | C26: EXTERN__SALES_OFFICE | D26: External sales office code | E26: The external sales office is an organizational unit within the sales organization representing geographic sales regions.The nomenclature contains a 2-digit legal entity identifier followed by a number (70–79). Serves as a selection criterion for sales documents and analyses. | F26: VARCHAR2(12) | H26: False | I26: HKA086 | J26: NOT NULL, text/mixed, max length 6 | K26: sales office; external sales office; regional sales office; commercial office
A27: AR_KeyDate | B27: Extern. Sales Office2 | C27: EXTERN__SALES_OFFICE2 | D27: External sales office code (TEXT) | F27: VARCHAR2(40) | H27: False | I27: MBDNO | J27: NOT NULL, text/mixed, max length 20
A28: AR_KeyDate | B28: FI-ML0 | C28: FI_ML0 | D28: Financial characteristic level 0 | E28: An internal characteristic from financial accounting (FI) representing a top-level classification (Level 0) for cross-company-code analyses. Used in integrated financial and management reporting. | F28: NUMBER(2) | H28: False | I28: 71 | J28: NOT NULL, integer only, max abs value 78 | K28: financial hierarchy; finance level 0; finance segment; reporting hierarchy
A29: AR_KeyDate | B29: FI-ML02 | C29: FI_ML02 | D29: Financial characteristic level 0 (TEXT) | F29: VARCHAR2(16) | H29: False | I29: TUR | J29: NOT NULL, text/mixed, max length 8
A30: AR_KeyDate | B30: Fiscal year/period | C30: FISCAL_YEAR_PERIOD | D30: Fiscal year / period | E30: Combination of fiscal year (e.g. 2025) and posting period (e.g. 001–012 for months). Serves as the time dimension in all SAP posting and controlling reports. | F30: NUMBER(10,4) | H30: False | I30: 12.026 | J30: NOT NULL, numeric, max prec/scale 10/4 | K30: fiscal period; fiscal month; accounting period; reporting period; fiscal year; period
A31: AR_KeyDate | B31: Fiscal year/period2 | C31: FISCAL_YEAR_PERIOD2 | D31: Fiscal year / period (TEXT) | F31: VARCHAR2(28) | H31: False | I31: Jan 26 | J31: NOT NULL, text/mixed, max length 14
A32: AR_KeyDate | B32: Int. Sales Group | C32: INT__SALES_GROUP | D32: Internal sales group | E32: An internal sales group is a sub-unit of a sales office. Employees are assigned to sales groups; a group is responsible for all line items in a sales document. | F32: VARCHAR2(6) | H32: False | I32: 0B0 | J32: NOT NULL, text/mixed, max length 3 | K32: sales group; internal sales group; sales team; commercial group
A33: AR_KeyDate | B33: Int. Sales Group2 | C33: INT__SALES_GROUP2 | D33: Internal sales group (TEXT) | F33: VARCHAR2(34) | H33: False | I33: MBVPR | J33: NOT NULL, text/mixed, max length 17
A34: AR_KeyDate | B34: Key Industry | C34: KEY_INDUSTRY | D34: Key industry | E34: An attribute that classifies the target industry of a customer or product (e.g. Automotive, Construction, Electronics). Used for market and industry segmentation in sales reporting. | F34: NUMBER(2) | H34: False | I34: 1 | J34: NOT NULL, integer only, max abs value 16 | K34: industry; industry segment; customer industry; market industry; sector
A35: AR_KeyDate | B35: Key Industry2 | C35: KEY_INDUSTRY2 | D35: Key industry (TEXT) | F35: VARCHAR2(40) | H35: False | I35: Automotive | J35: NOT NULL, text/mixed, max length 20
A36: AR_KeyDate | B36: Marketing Customer ship-to | C36: MARKETING_CUSTOMER_SHIP_TO | D36: Marketing customer (ship-to) | E36: An attribute in the customer master that assigns the ship-to party to a higher-level marketing customer. | F36: VARCHAR2(16) | H36: False | I36: 3530369 | J36: NOT NULL, text/mixed, max length 8 | K36: marketing customer ship-to; customer group ship-to; strategic ship-to customer
A37: AR_KeyDate | B37: Marketing Customer ship-to2 | C37: MARKETING_CUSTOMER_SHIP_TO2 | D37: Marketing customer (ship-to) (TEXT) | F37: VARCHAR2(70) | H37: False | I37: SUPREME NONWOVEN INDUSTRIES PVT.LTD | J37: NOT NULL, text/mixed, max length 35
A38: AR_KeyDate | B38: Marketing Customer sold-to | C38: MARKETING_CUSTOMER_SOLD_TO | D38: Marketing customer (sold-to) | E38: An attribute in the customer master that assigns the sold-to party to a higher-level marketing customer. | F38: VARCHAR2(16) | H38: False | I38: 3530369 | J38: NOT NULL, text/mixed, max length 8 | K38: marketing customer; global customer; strategic customer; corporate customer; parent customer
A39: AR_KeyDate | B39: Marketing Customer sold-to2 | C39: MARKETING_CUSTOMER_SOLD_TO2 | D39: Marketing customer (sold-to) (TEXT) | F39: VARCHAR2(70) | H39: False | I39: SUPREME NONWOVEN INDUSTRIES PVT.LTD | J39: NOT NULL, text/mixed, max length 35
A40: AR_KeyDate | B40: Marketing Level 0 | C40: MARKETING_LEVEL_0 | D40: Marketing level 0 (top level) | E40: Highest level of the internal marketing hierarchy. Typically corresponds to the reportable segment (e.g. "Performance Materials" or "Solutions & Specialties"). Serves as the highest aggregation level in product portfolio reporting. | F40: VARCHAR2(4) | H40: False | I40: 71 | J40: NOT NULL, text/mixed, max length 2 | K40: business segment; top marketing hierarchy; strategic segment; portfolio segment
A41: AR_KeyDate | B41: Marketing Level 02 | C41: MARKETING_LEVEL_02 | D41: Marketing level 0 (top level) (TEXT) | F41: VARCHAR2(16) | H41: False | I41: TUR | J41: NOT NULL, text/mixed, max length 8
...

Sheet 4. Metrics
A1: METRICS
A2: One row per metric the AI can compute. Each metric maps to a SQL pattern the AI instantiates at query time. keywords drive metric selection; critical_notes prevent common mistakes.
A3: ℹ Instructions: Add one row per supported metric. metric_name must be unique and match exactly how it is referenced in the GT sheet. keywords = comma-separated phrases a user might say (the AI selects the metric by matching these). sql_example uses {placeholders} for dynamic values (time filter, dimension columns, etc.) that the AI fills in at runtime. critical_notes = hard rules the AI must follow when using this metric — most important column for accuracy.
A4: Covestro | C4: (Covestro) | E4: (Covestro) | N4: Core Filter bei Sales, Qunatity, Margin, aber nicht bei OTIF & Receivables
A5: metric_name | B5: category | C5: description | D5: when_to_use | E5: formula | F5: keywords | G5: sql_example | H5: relevant_tables | I5: output_columns | J5: critical_notes | K5: example_args
A6: Var. Product Costs per kg | B6: Sales | C6: Variable product costs incurred per kilogram sold. Measures production cost efficiency relative to volume. Lower values generally indicate better cost efficiency. | D6: Use when the question asks for analyzing production cost efficiency, cost developments, margin drivers, product profitability, or benchmarking costs across products and business units. | E6: (KPI COSMOS: Product Costs, Var.) / (KPI COSMOS: Gross Sales Qty (in+ex)) | F6: Var./kg, variable cost per kg; product cost per kg; manufacturing cost per kg; production cost efficiency; cost/kg; unit production cost; variable manufacturing cost per kg; variable product cost analysis; variable cost performance | G6: SELECT {dimension_columns}, ROUND( SUM(cos.KPI_COSMOS__PRODUCT_COSTS__VAR) / NULLIF(SUM(cos.KPI_COSMOS__GROSS_SALES_QTY__I), 0), 2 ) AS product_costs_var_per_qty FROM cos WHERE {current_time_filter} AND {core_business_indicator} {dimension_filter_clauses} {group_by_clause} {order_by_clause} {limit_clause}; | H6: COSMOS | I6: product_costs_var_per_qty | K6: {"metric_name":"Product Costs Var per Qty","time_period":{"FISCAL_YEAR_PERIOD":"2025"},"dimensions":["PRODUCED_MATERIAL"],"order_by":"product_costs_var_per_qty DESC","limit":10}
A7: OTIF Rate | B7: OTIF | C7: Percentage of deliveries that were completed On Time and In Full quantity (OTIF). Measures customer service performance and supply chain reliability. | D7: Use when evaluating delivery performance and fulfillment quality. | E7: (KPI OTIF: # OTIF) / (KPI OTIF: # total deliveries) *100 | F7: OTIF; on time and in full; delivery performance; delivery reliability; fulfillment rate; customer service KPI; logistics KPI; shipment performance, percentage of OTIF-compliant deliveries, OTIF compliance | G7: SELECT {dimension_columns}, ROUND( SUM(o.KPI_OTIF____OTIF) * 100.0 / NULLIF(SUM(o.KPI_OTIF____TOTAL_DELIVERIES), 0), 2 ) AS otif_rate FROM o WHERE {current_time_filter} {dimension_filter_clauses} {group_by_clause} {order_by_clause} {limit_clause}; | H7: OTIF | I7: otif_rate | K7: {"metric_name":"OTIF Rate","time_period":{"FISCAL_YEAR_PERIOD":"2025"},"dimensions":["Marketing Customer ship-to"],"order_by":"otif_rate DESC","limit":10}
A8: WAT Target | B8: Working capital | C8: The amount-weighted contractual payment term days (target days) of all open receivable positions at the key date | D8: Use when comparing the WAT compared to the target and when assessing receivables management, customer payment terms and working capital targets | E8: (KPI AR-KeyDate: Weighted target days) / (KPI AR-KeyDate: Amount in EUR) | F8: WAT target; targeted weighted average payment term; payment target days; receivables target; customer payment terms; AR target days; collection terms; working capital target | G8: SELECT {dimension_columns}, ROUND( SUM(kd.KPI_AR_KEYDATE__WEIGHTED_TARGET_DAYS) / NULLIF(SUM(kd.KPI_AR_KEYDATE__AMOUNT_IN_EUR), 0), 2 ) AS wat_target FROM kd WHERE {current_time_filter} {dimension_filter_clauses} {group_by_clause} {order_by_clause} {limit_clause}; | H8: AR-KeyDate | I8: wat_target | K8: {"metric_name":"WAT Target","time_period":{"FISCAL_YEAR_PERIOD":"2025"},"dimensions":["PRODUCED_MATERIAL"],"order_by":"wat_target DESC","limit":10}
A9: WOC Target | B9: Working capital | C9: The weighted target days for Weeks of Credit (WoC) at the key date. Used as a benchmark figure against actual outstanding days. | D9: Use when analyzing the weeks of credit target | E9: (KPI AR-KeyDate: Weighted WoC Target days) / (KPI AR-KeyDate: Amount in EUR) | F9: weeks of credit target | G9: SELECT {dimension_columns}, ROUND( SUM(kd.KPI_AR_KEYDATE__WEIGHTED_WOC_TARGET_DAYS) / NULLIF(SUM(kd.KPI_AR_KEYDATE__AMOUNT_IN_EUR), 0), 2 ) AS woc_target FROM kd WHERE {current_time_filter} {dimension_filter_clauses} {group_by_clause} {order_by_clause} {limit_clause}; | H9: AR-KeyDate | I9: woc_target | K9: {"metric_name":"WOC Target","time_period":{"FISCAL_YEAR_PERIOD":"2025"},"dimensions":["PRODUCED_MATERIAL"],"order_by":"woc_target DESC","limit":10}
A10: MI1 in % | B10: Sales | C10: Consolidated Marginal Income I as a percentage of Net Sales | D10: Use when analyzing profitability and margin performance | E10: (KPI COSMOS: Consolidated Marginal Income I) / (KPI COSMOS: Net Sales) * 100 | F10: MI1in % Sales; Margin I, %; marginal income 1 percentage; contribution margin percentage; gross margin percentage; profitability ratio; margin analysis | G10: SELECT {dimension_columns}, ROUND(100.0 * SUM(cos.KPI_COSMOS__CONSOLIDATED_MARGIN_I) / NULLIF(SUM(cos.KPI_COSMOS__NET_SALES), 0), 2) AS m1_in_prozent FROM cos WHERE {current_time_filter} AND {core_business_indicator} {dimension_filter_clauses} {group_by_clause} {order_by_clause} {limit_clause}; | H10: COSMOS | I10: m1_in_prozent | K10: {"metric_name":"MI1 in %","time_period":{"FISCAL_YEAR_PERIOD":"2025"},"dimensions":["PRODUCED_MATERIAL"],"order_by":"m1_in_prozent DESC","limit":10}
A11: Margin I per kg | B11: Sales | C11: Consolidated Marginal Income I generated per kilogram sold. Shows the contribution earned for each unit of sales volume. | D11: Use when evaluating profitability per volume unit | E11: (KPI COSMOS: Consolidated Marginal Income I) / (KPI COSMOS: Gross Sales Qty (in+ex)) | F11: MI1 per kg; margin per kg; contribution per kg; profitability per kg; earnings per kg; unit contribution margin | G11: SELECT {dimension_columns}, ROUND( SUM(cos.KPI_COSMOS__CONSOLIDATED_MARGIN_I) / NULLIF(SUM(cos.KPI_COSMOS__GROSS_SALES_QTY__IN_EX), 0), 2 ) AS margin_I_per_kg FROM cos WHERE {current_time_filter} AND {core_business_indicator} {dimension_filter_clauses} {group_by_clause} {order_by_clause} {limit_clause}; | H11: COSMOS | I11: margin_I_per_kg | K11: {"metric_name":"Margin I per kg","time_period":{"FISCAL_YEAR_PERIOD":"2025"},"dimensions":["PRODUCED_MATERIAL"],"order_by":"margin_I_per_kg DESC","limit":10}
A12: MI2a in % | B12: Sales | C12: Consolidated Marginal Income IIa as a percentage of Net Sales. Reflects profitability after additional costs beyond MI1 and provides a deeper profitability view | D12: Use when assessing operational profitability (as of Marginal Income 2a) in comparison to Net sales | E12: (KPI COSMOS: Consolidated Marginal Income IIa) / (KPI COSMOS: Net Sales) | F12: MI2a in % Sales; Margin IIa, %; marginal income 2a percentage; operating margin; profitability ratio; contribution margin 2a; net sales profitability | G12: SELECT {dimension_columns}, ROUND(100.0 * SUM(cos.KPI_COSMOS__CONSOLIDATED_MARGIN_IIa) / NULLIF(SUM(cos.KPI_COSMOS__NET_SALES), 0), 2) AS MI2a_in_prozent FROM cos WHERE {current_time_filter} AND {core_business_indicator} {dimension_filter_clauses} {group_by_clause} {order_by_clause} {limit_clause}; | H12: COSMOS | I12: MI2a_in_prozent | K12: {"metric_name":"MI2a in %","time_period":{"FISCAL_YEAR_PERIOD":"2025"},"dimensions":["PRODUCED_MATERIAL"],"order_by":"MI2a_in_prozent DESC","limit":10}
A13: MI2a per kg | B13: Sales | C13: Consolidated Marginal Income IIa generated per kilogram sold. Measures profitability per unit after accounting for additional cost elements included in MI2a. | D13: Use when comparing profitability (as of Marginal Income 2a) by volume | E13: (KPI COSMOS: Consolidated Marginal Income IIa) / (KPI COSMOS: Gross Sales Qty (in+ex)) | F13: Margin 2a per kg; operating profit per kg; profitability per kg; contribution per kg; margin/kg; earnings per unit | G13: SELECT {dimension_columns}, ROUND( SUM(cos.KPI_COSMOS__CONSOLIDATED_MARGIN_IIa) / NULLIF(SUM(cos.KPI_COSMOS__GROSS_SALES_QTY__IN_EX), 0), 2 ) AS MI2a_per_kg FROM cos WHERE {current_time_filter} AND {core_business_indicator} {dimension_filter_clauses} {group_by_clause} {order_by_clause} {limit_clause}; | H13: COSMOS | I13: MI2a_per_kg | K13: {"metric_name":"MI2a per kg","time_period":{"FISCAL_YEAR_PERIOD":"2025"},"dimensions":["PRODUCED_MATERIAL"],"order_by":"MI2a_per_kg DESC","limit":10}
A14: Overdue | B14: Working capital | C14: Total value of receivables that have passed their due date and remain unpaid. Indicates collection issues and potential credit risk exposure. | D14: Use when monitoring overdue accounts, credit risk, collection performance, or receivables aging. | E14: KPI AR-KeyDate: Amount in EUR with net_due_date <= Fiscal year/period | F14: overdue receivables; overdue AR; outstanding overdue invoices; late payments; past due amount; receivables aging; collections backlog, past due date | G14: SELECT {dimension_columns}, SUM(kd.KPI_AR_KEYDATE__AMOUNT_IN_EUR) AS overdue_receivables_eur FROM kd WHERE net_due_date <= FISCAL_YEAR_PERIOD {current_time_filter} {dimension_filter_clauses} {group_by_clause} {order_by_clause} {limit_clause}; | H14: AR-KeyDate | I14: overdue_receivables_eur | K14: {"metric_name":"Overdue","time_period":{"FISCAL_YEAR_PERIOD":"2025"},"dimensions":["PRODUCED_MATERIAL"],"order_by":"overdue_receivables_eur DESC","limit":10}
A15: Not yet due | B15: Working capital | C15: Value of receivables that are still within their agreed payment terms and have not yet reached their due date2 | D15: Use when assessing current receivables | E15: (KPI AR-KeyDate: Amount in EUR) - (Overdue) | F15: current receivables; receivables within terms; open receivables; outstanding not overdue; current AR; receivables aging | G15: SELECT {dimension_columns}, ROUND( SUM(kd.KPI_AR_KEYDATE__AMOUNT_IN_EUR) - SUM(kd.overdue_receivables_eur), 2 ) AS not_yet_due FROM kd WHERE {current_time_filter} AND {core_business_indicator} {dimension_filter_clauses} {group_by_clause} {order_by_clause} {limit_clause}; | H15: AR-KeyDate | I15: not_yet_due | K15: {"metric_name":"Not yet due","time_period":{"FISCAL_YEAR_PERIOD":"2025"},"dimensions":["PRODUCED_MATERIAL"],"order_by":"not_yet_due DESC","limit":10}
A16: % Overdue of Receivables | B16: Working capital | C16: Percentage of total receivables that are overdue. Measures the quality of accounts receivable and effectiveness of collection efforts | D16: Use when evaluating the current receivables and the corresponding overdues | E16: (Overdue) / (KPI AR-KeyDate: Amount in EUR) | F16: overdue percentage; overdue receivables ratio; AR overdue rate; collections performance; past due percentage | G16: SELECT {dimension_columns}, ROUND( 100.0 * SUM(kd.overdue_receivables_eur) / SUM(kd.KPI_AR_KEYDATE__AMOUNT_IN_EUR), 2 ) AS prozent_overdue_of_receivables FROM kd WHERE {current_time_filter} {dimension_filter_clauses} {group_by_clause} {order_by_clause} {limit_clause}; | H16: AR-KeyDate | I16: prozent_overdue_of_receivables | K16: {"metric_name":"% Overdue of Receivables","time_period":{"FISCAL_YEAR_PERIOD":"2025"},"dimensions":["PRODUCED_MATERIAL"],"order_by":"prozent_overdue_of_receivables DESC","limit":10}
A17: Volume Growth (%) | B17: Sales | C17: Percentage change in order volume compared with a prior period. Measures demand development | D17: Use when comparing order volume across two periods (e.g. June 2025 vs June 2026). Requires both time_period (current) and comparison_period (baseline). | E17: ((KPI Sales: Delivery Quantity KG_current -KPI Sales: Delivery Quantity KG_prior) / KPI Sales: Delivery Quantity KG_prior) * 100 | F17: order volume growth; sales volume growth; quantity growth; shipment growth; demand growth; volume trend; volume change; sales quantity increase; sales quantity decrease | G17: WITH totals AS ( SELECT {dimension_columns}, SUM(CASE WHEN s.ACT__GI_DAY BETWEEN TO_DATE('{current_start_date}') AND TO_DATE('{current_end_date}') THEN s.KPI_SALES__DELIVERY_QUANTITY_KG ELSE 0 END) AS current_total, SUM(CASE WHEN s.ACT__GI_DAY BETWEEN TO_DATE('{prior_start_date}') AND TO_DATE('{prior_end_date}') THEN s.KPI_SALES__DELIVERY_QUANTITY_KG ELSE 0 END) AS prior_total FROM s WHERE s.CORE_BUSINESS_INDICATOR IN ('C', 'P', 'T') AND (s.ACT__GI_DAY BETWEEN TO_DATE('{current_start_date}') AND TO_DATE('{current_end_date}') OR s.ACT__GI_DAY BETWEEN TO_DATE('{prior_start_date}') AND TO_DATE('{prior_end_date}')) {dimension_filter_clauses} {group_by_clause} ) SELECT {dimension_columns}, ROUND(current_total, 2) AS current_total, ROUND(prior_total, 2) AS prior_total, ROUND(current_total - prior_total, 2) AS absolute_change, ROUND(100.0 * (current_total - prior_total) / NULLIF(prior_total, 0), 2) AS volume_growth_prozent FROM totals {order_by_clause} {limit_clause}; | H17: Sales | I17: current_total, prior_total, absolute_change, volume_growth_prozent | K17: {"metric_name":"Volume Growth (%)","time_period":{"FISCAL_YEAR_PERIOD":"2025"},"dimensions":["PRODUCED_MATERIAL"],"order_by":"volume_growth_prozent DESC","limit":10}
A18: Net Sales Growth (%) | B18: Sales | C18: Percentage change in Net Sales between a current period and a comparable prior period (YoY, QoQ, MoM). Measures topline momentum. | D18: Use when comparing Net Sales across two periods (e.g. June 2025 vs June 2026). Requires both time_period (current) and comparison_period (baseline). | E18: ((COPA Net sales_current - COPA Net sales_prior) / COPA Net sales_prior) * 100 | F18: net sales growth; net sales change; growth in Net Sales; compare net sales; net sales YoY; net sales QoQ; net sales MoM; topline growth; net sales increase; net sales momentum; net sales trend; delta in net sales | G18: WITH totals AS ( SELECT {dimension_columns}, SUM(CASE WHEN cop.POSTING_DATE BETWEEN TO_DATE('{current_start_date}') AND TO_DATE('{current_end_date}') THEN cop.KPI_COPA__NET_SALES ELSE 0 END) AS current_total, SUM(CASE WHEN cop.POSTING_DATE BETWEEN TO_DATE('{prior_start_date}') AND TO_DATE('{prior_end_date}') THEN cop.KPI_COPA__NET_SALES ELSE 0 END) AS prior_total FROM cop WHERE cop.CORE_BUSINESS_INDICATOR IN ('C', 'P', 'T') AND (cop.POSTING_DATE BETWEEN TO_DATE('{current_start_date}') AND TO_DATE('{current_end_date}') OR cop.POSTING_DATE BETWEEN TO_DATE('{prior_start_date}') AND TO_DATE('{prior_end_date}')) {dimension_filter_clauses} {group_by_clause} ) SELECT {dimension_columns}, ROUND(current_total, 2) AS current_total, ROUND(prior_total, 2) AS prior_total, ROUND(current_total - prior_total, 2) AS absolute_change, ROUND(100.0 * (current_total - prior_total) / NULLIF(prior_total, 0), 2) AS metric_value FROM totals {order_by_clause} {limit_clause}; | H18: Sales | I18: current_total, comparison_total, absolute_change | J18: WITHIN-YEAR QoQ (same year, different quarters): Do NOT use this metric — it compares to prior year's same quarter. Use net sales with sequential_delta=true and quarter in dimensions instead. MULTI-YEAR TREND (3+ years): Use net sales with sequential_delta=true, not this metric. Always present all four output columns: current_total, comparison_total, absolute_change, metric_value (%). | K18: {"metric_name":"net sales Growth (%)","time_period":{"fiscal_year":"2024"},"comparison_period":{"fiscal_year":"2023"},"dimensions":["region_name"],"order_by":"absolute_change DESC"}
A19: Selling Price | B19: Sales | C19: Average net selling price per unit (kg) sold. Measures realized pricing and supports pricing strategy | D19: Use when analyzing pricing performance, price realization, price changes, product mix effects, and driver of net sales & order volume | E19: (KPI COPA: Net sales) / (KPI COPA: Gross Sales Qty) | F19: selling price; average selling price; ASP; price per kg; realized price; sales price; unit price; net price; pricing analysis; pricing KPI | G19: SELECT {dimension_columns}, ROUND( SUM(cop.KPI_COPA__NET_SALES) / NULLIF(SUM(cop.KPI_COPA__GROSS_SALES_QTY), 0), 2 ) AS selling_price FROM cop WHERE {current_time_filter} AND {core_business_indicator} {dimension_filter_clauses} {group_by_clause} {order_by_clause} {limit_clause}; | H19: COPA | I19: selling_price | K19: {"metric_name":"Selling Price","time_period":{"FISCAL_YEAR_PERIOD":"2025"},"dimensions":["PRODUCED_MATERIAL"],"order_by":"selling_price DESC","limit":10}
A20: Receivables | B20: Working capital | C20: =VLOOKUP(E20,'3. Column Info'!B6:E102,4,FALSE) -> The open receivables amount in EUR at a defined key date. Part of the accounts receivable key date reporting. Used for WoC and receivables stock analyses. | D20: Use when analyzing total accounts receivable exposure, outstanding customer balances, receivables stock, working capital tied up in customers, customer credit exposure, or regional/customer-level AR balances at a specific reporting date. Do not use for collection performance or payment behavior trends over time; use AR-PM metrics instead. | E20: KPI AR-KeyDate: Amount in EUR | F20: receivables; accounts receivable; AR balance; outstanding receivables; open invoices | G20: SELECT KPI_AR_KEYDATE__AMOUNT_IN_EUR FROM kd | H20: AR-KeyDate
A21: Line items | B21: Working capital | C21: =VLOOKUP(E21,'3. Column Info'!B7:E103,4,FALSE) -> Number of open customer line items (receivable positions) at the defined key date. Serves as the volume basis for average value calculations in AR key date reporting. | D21: Use when analyzing the number of open receivables, invoice volume, customer open-item exposure, receivables portfolio size, or as a denominator for weighted AR calculations. Do not use as a measure of monetary exposure. | E21: KPI AR-KeyDate: Counter | F21: receivable count; invoice count; open item count; line item count | G21: SELECT KPI_AR_KEYDATE__COUNTER FROM kd | H21: AR-KeyDate
A22: Net value of billing item | B22: Working capital | C22: =VLOOKUP(E22,'3. Column Info'!B8:E104,4,FALSE) -> The net value of an invoice line item in document currency (DC) at the key date. Starting figure for the calculation of weighted receivables KPIs such as WoC and WAT. | D22: Use when analyzing invoice-level receivables values, billing values in document currency, or when calculating weighted working-capital metrics such as WAT and WoC. Do not use for consolidated reporting in EUR. | E22: KPI AR-KeyDate: Net Value of Billing Item (DC) | F22: invoice value; billing value; receivable value; invoice amount | G22: SELECT KPI_AR_KEYDATE__NET_VALUE_OF_BILLING_ITEM FROM kd | H22: AR-KeyDate
A23: Weighted WoC target days | B23: Working capital | C23: =VLOOKUP(E23,'3. Column Info'!B9:E105,4,FALSE) -> The weighted target days for Weeks of Credit (WoC) at the key date, calculated on the basis of agreed payment terms. Used as a benchmark figure against actual outstanding days. The actual Weighted WoC Target days is calculated by dividing Weighted WoC Target days by Amount in EUR for each data point. | D23: Use when evaluating target payment terms, benchmark credit conditions, contractual customer payment agreements, or working-capital targets. Useful for comparing actual receivables performance against target conditions. | E23: KPI AR-KeyDate: Weighted WoC Target days | F23: WOC target; weeks of credit target; target credit days | G23: SELECT KPI_AR_KEYDATE__WEIGHTED_WOC_TARGET_DAYS FROM kd | H23: AR-KeyDate
A24: Weighted target days | B24: Working capital | C24: =VLOOKUP(E24,'3. Column Info'!B10:E106,4,FALSE) -> The amount-weighted contractual payment term days (target days) of all open receivable positions at the key date. Basis for the calculation of WAT (Weighted Average Terms). The actual weighted target days is calculated by dividing Weighted target days by Amount in EUR for each data point. | D24: Use when analyzing average contractual payment terms across a receivables portfolio, customer term structures, or WAT calculations. Do not use to assess actual payment behavior. | E24: KPI AR-KeyDate: Weighted target days | F24: WAT target; payment target days; target payment terms | G24: SELECT KPI_AR_KEYDATE__WEIGHTED_TARGET_DAYS FROM kd | H24: AR-KeyDate
A25: Receivables - PM | B25: Working capital | C25: =VLOOKUP(E25,Tabelle14[[column_name]:[description]],4,FALSE) -> The receivables amount in EUR within the AR Performance Monitoring (AR-PM). Period-related figure for evaluating receivables performance. | D25: Use when monitoring receivables performance over a reporting period, evaluating working-capital performance, or tracking AR trends over time. Do not use for balance-sheet snapshots at a specific key date. | E25: KPI AR-PM: Amount EUR | F25: receivables amount; AR amount; outstanding balance | G25: SELECT KPI_AR_PM__AMOUNT_EUR FROM pm | H25: AR-PM
A26: Line items - PM | B26: Working capital | C26: =VLOOKUP(E26,'3. Column Info'!B$197:E$604,4,FALSE) -> Number of customer line items in AR Performance Monitoring. Volume basis for weighted average KPIs in AR period reporting. | D26: Use when analyzing the volume of receivable positions in period-based AR performance reporting or when calculating weighted average AR indicators. Do not use for monetary analyses. | E26: KPI AR-PM: Counter | F26: item count; invoice count; receivable count | G26: SELECT KPI_AR_PM__COUNTER FROM pm | H26: AR-PM
A27: WoC deviation from target | B27: Working capital | C27: =VLOOKUP(E27,'3. Column Info'!B$197:E$604,4,FALSE) -> The difference between actual WoC (Weeks of Credit) and the target value. Positive value = payment term exceeded; negative value = payment term undercut. Operational control indicator for receivables management. | D27: Use when evaluating whether actual customer payment performance exceeds or misses working-capital targets. Useful for working-capital reviews, collection management, and AR performance monitoring. Positive values indicate deterioration versus target. | E27: KPI AR-PM: Diff WoC Target | F27: WOC deviation; variance to target WoC; credit term variance; week of credit deviation | G27: SELECT KPI_AR_PM__DIFF_WOC_TARGET FROM pm | H27: AR-PM
A28: Effective days outstanding | B28: Working capital | C28: =VLOOKUP(E28,'3. Column Info'!B$197:E$604,4,FALSE) -> EDO = WAT + WDD. Indicates the actual weighted outstanding days, i.e. the sum of the agreed payment terms (WAT) and the average delay (WDD). Corresponds to the operational DSO (Days Sales Outstanding). | D28: Use when measuring actual weighted customer payment duration, operational DSO performance, collection effectiveness, or customer payment behavior. Use as the primary KPI for outstanding receivables duration. | E28: KPI AR-PM: EDO (Effective Days Outstanding) | F28: EDO; days outstanding; operational DSO; collection days | G28: SELECT KPI_AR_PM__EDO__EFFECTIVE_DAYS_OUTSTANDING FROM pm | H28: AR-PM
